Workbook

Sheet 전력비
B1: [년도별 전력비 현황 ]
C2: 단위 | D2: 년도 | E2: 1월 | F2: 2월 | G2: 3월 | H2: 4월 | I2: 5월 | J2: 6월 | K2: 7월 | L2: 8월 | M2: 9월 | N2: 10월 | O2: 11월 | P2: 12월 | Q2: 평균 | R2: 비고
B4: 총 전기 요금 | C4: 백만원 | D4: '07 | E4: =94707260/1000000 -> 94.70726 | F4: =91556520/1000000 -> 91.55652 | G4: =101391180/1000000 -> 101.39118 | H4: =89800762/1000000 -> 89.800762 | I4: =94576360/1000000 -> 94.57636 | J4: =91200860/1000000 -> 91.20086 | K4: =105923400/1000000 -> 105.9234 | L4: =102615940/1000000 -> 102.61594 | M4: =81217980/1000000 -> 81.21798 | N4: =99696640/1000000 -> 99.69664 | O4: =117617420/1000000 -> 117.61742 | P4: =115819160/1000000 -> 115.81916 | Q4: =+AVERAGE(E4:P4) -> 98.843624
D5: '08 | E5: =118569920/1000000 -> 118.56992 | F5: =104524130/1000000 -> 104.52413 | G5: =110212640/1000000 -> 110.21264 | H5: =113787940/1000000 -> 113.78794 | I5: =105360450/1000000 -> 105.36045 | J5: =100766330/1000000 -> 100.76633 | K5: =136284590/1000000 -> 136.28459 | L5: =118771250/1000000 -> 118.77125 | M5: =85020070/1000000 -> 85.02007 | N5: =114174410/1000000 -> 114.17441 | O5: =126248700/1000000 -> 126.2487 | P5: =125505530/1000000 -> 125.50553 | Q5: =+AVERAGE(E5:P5) -> 113.26883
D6: '09 | E6: =94136640/1000000 -> 94.13664 | F6: =105299660/1000000 -> 105.29966 | G6: =105252240/1000000 -> 105.25224 | H6: =107815080/1000000 -> 107.81508 | I6: =100569570/1000000 -> 100.56957 | J6: =109120510/1000000 -> 109.12051 | K6: =167232710/1000000 -> 167.23271 | L6: =123399390/1000000 -> 123.39939 | M6: =138274310/1000000 -> 138.27431 | N6: =133126500/1000000 -> 133.1265 | O6: =165431780/1000000 -> 165.43178 | P6: =+[1]월별!#REF!/1000000 -> #REF! | Q6: =+AVERAGE(E6:P6) -> #REF!
D7: '10 | E7: =+[1]월별!#REF!/1000000 -> #REF! | F7: =+[1]월별!#REF!/1000000 -> #REF! | G7: =+[1]월별!#REF!/1000000 -> #REF! | H7: =+[1]월별!#REF!/1000000 -> #REF! | I7: =+[1]월별!#REF!/1000000 -> #REF! | J7: =+[1]월별!#REF!/1000000 -> #REF! | K7: =+[1]월별!#REF!/1000000 -> #REF! | L7: =+[1]월별!#REF!/1000000 -> #REF! | ... P7: =+[1]월별!#REF!/1000000 -> #REF! | Q7: =+AVERAGE(E7:P7) -> #REF!
D8: '11 | E8: =[1]월별!#REF!/1000000 -> #REF! | F8: =[1]월별!#REF!/1000000 -> #REF! | G8: =[1]월별!#REF!/1000000 -> #REF! | H8: =[1]월별!#REF!/1000000 -> #REF! | I8: =[1]월별!#REF!/1000000 -> #REF! | J8: =[1]월별!#REF!/1000000 -> #REF! | K8: =[1]월별!#REF!/1000000 -> #REF! | L8: =[1]월별!#REF!/1000000 -> #REF! | ... P8: =[1]월별!#REF!/1000000 -> #REF! | Q8: =+AVERAGE(E8:P8) -> #REF!
D9: 12 | E9: =[1]월별!#REF!/1000000 -> #REF! | F9: =[1]월별!#REF!/1000000 -> #REF! | G9: =[1]월별!#REF!/1000000 -> #REF! | H9: =[1]월별!#REF!/1000000 -> #REF! | I9: =[1]월별!#REF!/1000000 -> #REF! | J9: =[1]월별!#REF!/1000000 -> #REF! | K9: =[1]월별!#REF!/1000000 -> #REF! | L9: =[1]월별!#REF!/1000000 -> #REF! | ... P9: =[1]월별!#REF!/1000000 -> #REF! | Q9: =+AVERAGE(E9:P9) -> #REF!
D10: '13 | E10: =[1]월별!#REF!/1000000 -> #REF! | F10: =[1]월별!#REF!/1000000 -> #REF! | G10: =[1]월별!#REF!/1000000 -> #REF! | H10: =[1]월별!#REF!/1000000 -> #REF! | I10: =[1]월별!#REF!/1000000 -> #REF! | J10: =[1]월별!#REF!/1000000 -> #REF! | K10: =[1]월별!#REF!/1000000 -> #REF! | L10: =[1]월별!#REF!/1000000 -> #REF! | ... P10: =[1]월별!#REF!/1000000 -> #REF! | Q10: =+AVERAGE(E10:P10) -> #REF!
D11: '14 | E11: =[1]월별!#REF!/1000000 -> #REF! | F11: =[1]월별!#REF!/1000000 -> #REF! | G11: =[1]월별!#REF!/1000000 -> #REF! | H11: =[1]월별!#REF!/1000000 -> #REF! | I11: =[1]월별!#REF!/1000000 -> #REF! | J11: =[1]월별!#REF!/1000000 -> #REF! | K11: =[1]월별!#REF!/1000000 -> #REF! | L11: =[1]월별!#REF!/1000000 -> #REF! | ... P11: =[1]월별!#REF!/1000000 -> #REF! | Q11: =+AVERAGE(E11:P11) -> #REF!
D12: '15 | E12: =[1]월별!#REF!/1000000 -> #REF! | F12: =[1]월별!#REF!/1000000 -> #REF! | G12: =[1]월별!#REF!/1000000 -> #REF! | H12: =[1]월별!#REF!/1000000 -> #REF! | I12: =[1]월별!#REF!/1000000 -> #REF! | J12: =[1]월별!#REF!/1000000 -> #REF! | K12: =[1]월별!#REF!/1000000 -> #REF! | L12: =[1]월별!#REF!/1000000 -> #REF! | ... P12: =[1]월별!#REF!/1000000 -> #REF! | Q12: =+AVERAGE(E12:P12) -> #REF!
D13: '16 | E13: =[1]월별!#REF!/1000000 -> #REF! | F13: =[1]월별!#REF!/1000000 -> #REF! | G13: =[1]월별!#REF!/1000000 -> #REF! | H13: =[1]월별!#REF!/1000000 -> #REF! | I13: =[1]월별!#REF!/1000000 -> #REF! | J13: =[1]월별!#REF!/1000000 -> #REF! | K13: =[1]월별!#REF!/1000000 -> #REF! | L13: =[1]월별!#REF!/1000000 -> #REF! | ... P13: =[1]월별!#REF!/1000000 -> #REF! | Q13: =+AVERAGE(E13:P13) -> #REF!
D14: '17 | E14: =[1]월별!#REF!/1000000 -> #REF! | F14: =[1]월별!#REF!/1000000 -> #REF! | G14: =[1]월별!#REF!/1000000 -> #REF! | H14: =[1]월별!#REF!/1000000 -> #REF! | I14: =[1]월별!#REF!/1000000 -> #REF! | J14: =[1]월별!#REF!/1000000 -> #REF! | K14: =[1]월별!#REF!/1000000 -> #REF! | L14: =[1]월별!#REF!/1000000 -> #REF! | ... P14: =[1]월별!#REF!/1000000 -> #REF! | Q14: =+AVERAGE(E14:P14) -> #REF!
D15: '18 | E15: =[1]월별!#REF!/1000000 -> #REF! | F15: =[1]월별!#REF!/1000000 -> #REF! | G15: =[1]월별!#REF!/1000000 -> #REF! | H15: =[1]월별!#REF!/1000000 -> #REF! | I15: =[1]월별!#REF!/1000000 -> #REF! | J15: =[1]월별!#REF!/1000000 -> #REF! | K15: =[1]월별!#REF!/1000000 -> #REF! | L15: =[1]월별!#REF!/1000000 -> #REF! | ... P15: =[1]월별!#REF!/1000000 -> #REF! | Q15: =+AVERAGE(E15:P15) -> #REF!
D16: '19 | E16: =[1]월별!#REF!/1000000 -> #REF! | F16: =[1]월별!#REF!/1000000 -> #REF! | G16: =[1]월별!#REF!/1000000 -> #REF! | H16: =[1]월별!#REF!/1000000 -> #REF! | I16: =[1]월별!#REF!/1000000 -> #REF! | J16: =[1]월별!#REF!/1000000 -> #REF! | K16: =[1]월별!#REF!/1000000 -> #REF! | L16: =[1]월별!#REF!/1000000 -> #REF! | ... P16: =[1]월별!#REF!/1000000 -> #REF! | Q16: =+AVERAGE(E16:P16) -> #REF!
D17: '20 | E17: =[1]월별!G38/1000000 -> 307.48096 | F17: =[1]월별!H38/1000000 -> 274.40757 | G17: =[1]월별!I38/1000000 -> 260.95025 | H17: =[1]월별!J38/1000000 -> 231.78908 | I17: =[1]월별!K38/1000000 -> 184.61559 | J17: =[1]월별!L38/1000000 -> 287.01457 | K17: =[1]월별!M38/1000000 -> 336.25847 | L17: =[1]월별!N38/1000000 -> 274.74934 | ... P17: =[1]월별!R38/1000000 -> 358.23924 | Q17: =+AVERAGE(E17:P17) -> 283.15413
D18: '21 | E18: =[1]월별!S38/1000000 -> 330.78196 | F18: =[1]월별!T38/1000000 -> 307.55459 | G18: =[1]월별!U38/1000000 -> 274.15259 | H18: =[1]월별!V38/1000000 -> 268.73851 | I18: =[1]월별!W38/1000000 -> 248.51325 | J18: =[1]월별!X38/1000000 -> 319.26218 | K18: =[1]월별!Y38/1000000 -> 342.58215 | L18: =[1]월별!Z38/1000000 -> 277.30772 | ... P18: =[1]월별!AD38/1000000 -> 350.80932 | Q18: =+AVERAGE(E18:P18) -> 293.17662
D19: '22 | E19: =[1]월별!AE38/1000000 -> 347.90669 | F19: =[1]월별!AF38/1000000 -> 317.23138 | G19: =[1]월별!AG38/1000000 -> 253.39872 | H19: =[1]월별!AH38/1000000 -> 248.36276 | I19: =[1]월별!AI38/1000000 -> 280.84282 | J19: =[1]월별!AJ38/1000000 -> 347.30455 | K19: =[1]월별!AK38/1000000 -> 365.65539 | L19: =[1]월별!AL38/1000000 -> 306.88253 | ... P19: =[1]월별!AP38/1000000 -> 439.33532 | Q19: =+AVERAGE(E19:P19) -> 328.34651
D20: '23 | E20: =[1]월별!AQ38/1000000 -> 468.74468 | F20: =[1]월별!AR38/1000000 -> 449.58973 | G20: =[1]월별!AS38/1000000 -> 406.64965 | H20: =[1]월별!AT38/1000000 -> 377.69385 | I20: =[1]월별!AU38/1000000 -> 388.85077 | J20: =[1]월별!AV38/1000000 -> 433.3384 | K20: =[1]월별!AW38/1000000 -> 418.28948 | L20: =[1]월별!AX38/1000000 -> 417.16183 | ... P20: =[1]월별!BB38/1000000 -> 411.90695 | Q20: =+AVERAGE(E20:P20) -> 410.60515 | R20: [산업용 전기요금 단가 변화] - '23년 : 153.7원/Kwh - '24년 : 168.2원/Kwh - '25년 : 182.8원/Kwh - '26년 : 전기요금 체제 개편안 시행(별첨, 4/16~) [ 단가 인상 시점] - '23년 11월 ~ : 10.6원/Kwh 인상 - '24년 10월말~ : 9.7% 인상
D21: '24 | E21: =[1]월별!BC38/1000000 -> 481.02239 | F21: =[1]월별!BD38/1000000 -> 429.58587 | G21: =[1]월별!BE38/1000000 -> 389.6561 | H21: =[1]월별!BF38/1000000 -> 379.23181 | I21: =[1]월별!BG38/1000000 -> 375.54378 | J21: =[1]월별!BH38/1000000 -> 441.41839 | K21: =[1]월별!BI38/1000000 -> 415.39849 | L21: =[1]월별!BJ38/1000000 -> 423.27445 | ... P21: =[1]월별!BN38/1000000 -> 493.66654 | Q21: =+AVERAGE(E21:P21) -> 421.30257
D22: '25 | E22: =[1]월별!BO38/1000000 -> 471.60722 | F22: =[1]월별!BP38/1000000 -> 484.05639 | G22: =[1]월별!BQ38/1000000 -> 441.49142 | H22: =[1]월별!BR38/1000000 -> 430.06834 | I22: =[1]월별!BS38/1000000 -> 435.28829 | J22: =[1]월별!BT38/1000000 -> 470.98455 | K22: =[1]월별!BU38/1000000 -> 419.36332 | L22: =[1]월별!BV38/1000000 -> 410.11799 | ... P22: =[1]월별!BZ38/1000000 -> 444.93493 | Q22: =+AVERAGE(E22:P22) -> 432.65943
D23: '26 | E23: =[1]월별!CA38/1000000 -> 472.6216 | F23: =[1]월별!CB38/1000000 -> 405.42731 | G23: =404961107/1000000 -> 404.96111 | H23: 387.76984 | Q23: =+AVERAGE(E23:P23) -> 417.69496
B24: 근무일수 | C24: 일 | D24: '07 | E24: 24.2 | F24: 23.07 | G24: 27 | H24: 26.3 | I24: 28.33 | J24: 27 | K24: 22.7 | L24: 22.7 | M24: 22.75 | N24: 29.55 | O24: 29 | P24: 28.5 | Q24: =+AVERAGE(E24:P24) -> 25.925
D25: '08 | E25: 28 | F25: 23.65 | G25: 27.54 | H25: 7312.576 | I25: 21.92 | J25: 21.45 | K25: 22.6 | L25: 19.9 | M25: 16.9 | N25: 25.2 | O25: 20.75 | P25: 17.6 | Q25: =+AVERAGE(E25:P25) -> 629.8405
D26: '09 | E26: 11 | F26: 15 | G26: 18.6 | H26: 0.32337059 | I26: 18.2 | J26: 21.1 | K26: 23.8 | L26: 16.9 | M26: 26.9 | N26: 25 | O26: 26.65 | P26: =+[1]월별!#REF! -> #REF! | Q26: =+AVERAGE(E26:P26) -> #REF!
D27: '10 | E27: =+[1]월별!#REF! -> #REF! | F27: =+[1]월별!#REF! -> #REF! | G27: =+[1]월별!#REF! -> #REF! | H27: =+[1]월별!#REF! -> #REF! | I27: =+[1]월별!#REF! -> #REF! | J27: =+[1]월별!#REF! -> #REF! | K27: =+[1]월별!#REF! -> #REF! | L27: =+[1]월별!#REF! -> #REF! | ... P27: =+[1]월별!#REF! -> #REF! | Q27: =+AVERAGE(E27:P27) -> #REF!
D28: '11 | E28: =[1]월별!#REF! -> #REF! | F28: =[1]월별!#REF! -> #REF! | G28: =[1]월별!#REF! -> #REF! | H28: =[1]월별!#REF! -> #REF! | I28: =[1]월별!#REF! -> #REF! | J28: =[1]월별!#REF! -> #REF! | K28: =[1]월별!#REF! -> #REF! | L28: =[1]월별!#REF! -> #REF! | ... P28: =[1]월별!#REF! -> #REF! | Q28: =+AVERAGE(E28:P28) -> #REF!
D29: "12 | E29: =[1]월별!#REF! -> #REF! | F29: =[1]월별!#REF! -> #REF! | G29: =[1]월별!#REF! -> #REF! | H29: =[1]월별!#REF! -> #REF! | I29: =[1]월별!#REF! -> #REF! | J29: =[1]월별!#REF! -> #REF! | K29: =[1]월별!#REF! -> #REF! | L29: =[1]월별!#REF! -> #REF! | ... P29: =[1]월별!#REF! -> #REF! | Q29: =+AVERAGE(E29:P29) -> #REF!
D30: '13 | E30: =[1]월별!#REF! -> #REF! | F30: =[1]월별!#REF! -> #REF! | G30: =[1]월별!#REF! -> #REF! | H30: =[1]월별!#REF! -> #REF! | I30: =[1]월별!#REF! -> #REF! | J30: =[1]월별!#REF! -> #REF! | K30: =[1]월별!#REF! -> #REF! | L30: =[1]월별!#REF! -> #REF! | ... P30: =[1]월별!#REF! -> #REF! | Q30: =+AVERAGE(E30:P30) -> #REF!
D31: '14 | E31: =[1]월별!#REF! -> #REF! | F31: =[1]월별!#REF! -> #REF! | G31: =[1]월별!#REF! -> #REF! | H31: =[1]월별!#REF! -> #REF! | I31: =[1]월별!#REF! -> #REF! | J31: =[1]월별!#REF! -> #REF! | K31: =[1]월별!#REF! -> #REF! | L31: =[1]월별!#REF! -> #REF! | ... P31: =[1]월별!#REF! -> #REF! | Q31: =+AVERAGE(E31:P31) -> #REF!
D32: '15 | E32: =[1]월별!#REF! -> #REF! | F32: =[1]월별!#REF! -> #REF! | G32: =[1]월별!#REF! -> #REF! | H32: =[1]월별!#REF! -> #REF! | I32: =[1]월별!#REF! -> #REF! | J32: =[1]월별!#REF! -> #REF! | K32: =[1]월별!#REF! -> #REF! | L32: =[1]월별!#REF! -> #REF! | ... P32: =[1]월별!#REF! -> #REF! | Q32: =+AVERAGE(E32:P32) -> #REF!
D33: '16 | E33: =[1]월별!#REF! -> #REF! | F33: =[1]월별!#REF! -> #REF! | G33: =[1]월별!#REF! -> #REF! | H33: =[1]월별!#REF! -> #REF! | I33: =[1]월별!#REF! -> #REF! | J33: =[1]월별!#REF! -> #REF! | K33: =[1]월별!#REF! -> #REF! | L33: =[1]월별!#REF! -> #REF! | ... P33: =[1]월별!#REF! -> #REF! | Q33: =+AVERAGE(E33:P33) -> #REF!
D34: '17 | E34: =[1]월별!#REF! -> #REF! | F34: =[1]월별!#REF! -> #REF! | G34: =[1]월별!#REF! -> #REF! | H34: =[1]월별!#REF! -> #REF! | I34: =[1]월별!#REF! -> #REF! | J34: =[1]월별!#REF! -> #REF! | K34: =[1]월별!#REF! -> #REF! | L34: =[1]월별!#REF! -> #REF! | ... P34: =[1]월별!#REF! -> #REF! | Q34: =+AVERAGE(E34:P34) -> #REF!
D35: '18 | E35: =[1]월별!#REF! -> #REF! | F35: =[1]월별!#REF! -> #REF! | G35: =[1]월별!#REF! -> #REF! | H35: =[1]월별!#REF! -> #REF! | I35: =[1]월별!#REF! -> #REF! | J35: =[1]월별!#REF! -> #REF! | K35: =[1]월별!#REF! -> #REF! | L35: =[1]월별!#REF! -> #REF! | ... P35: =[1]월별!#REF! -> #REF! | Q35: =+AVERAGE(E35:P35) -> #REF!
D36: '19 | E36: =[1]월별!#REF! -> #REF! | F36: =[1]월별!#REF! -> #REF! | G36: =[1]월별!#REF! -> #REF! | H36: =[1]월별!#REF! -> #REF! | I36: =[1]월별!#REF! -> #REF! | J36: =[1]월별!#REF! -> #REF! | K36: =[1]월별!#REF! -> #REF! | L36: =[1]월별!#REF! -> #REF! | ... P36: =[1]월별!#REF! -> #REF! | Q36: =+AVERAGE(E36:P36) -> #REF!
D37: '20 | E37: =[1]월별!G39 -> 24.5 | F37: =[1]월별!H39 -> 20.2 | G37: =[1]월별!I39 -> 28.5 | H37: =[1]월별!J39 -> 24.5 | I37: =[1]월별!K39 -> 17.5 | J37: =[1]월별!L39 -> 21 | K37: =[1]월별!M39 -> 27.1 | L37: =[1]월별!N39 -> 22.1 | ... P37: =[1]월별!R39 -> 28.1 | Q37: =+AVERAGE(E37:P37) -> 24.983333
D38: '21 | E38: =[1]월별!S39 -> 24.7 | F38: =[1]월별!T39 -> 24.7 | G38: =[1]월별!U39 -> 29.7 | H38: =[1]월별!V39 -> 29.4 | I38: =[1]월별!W39 -> 27 | J38: =[1]월별!X39 -> 25.5 | K38: =[1]월별!Y39 -> 29 | L38: =[1]월별!Z39 -> 21.9 | ... P38: =[1]월별!AD39 -> 27.2 | Q38: =+AVERAGE(E38:P38) -> 26.066667
D39: '22 | E39: =[1]월별!AE39 -> 28.9 | F39: =[1]월별!AF39 -> 24 | G39: =[1]월별!AG39 -> 23.5 | H39: =[1]월별!AH39 -> 22.8 | I39: =[1]월별!AI39 -> 27.9 | J39: =[1]월별!AJ39 -> 28 | K39: =[1]월별!AK39 -> 27.5 | L39: =[1]월별!AL39 -> 22 | ... P39: =[1]월별!AP39 -> 29 | Q39: =+AVERAGE(E39:P39) -> 26.308333
D40: '23 | E40: =[1]월별!AQ39 -> 28.57 | F40: =[1]월별!AR39 -> 26.9 | G40: =[1]월별!AS39 -> 29.97 | H40: =[1]월별!AT39 -> 27.87 | I40: =[1]월별!AU39 -> 28.71 | J40: =[1]월별!AV39 -> 25.93 | K40: =[1]월별!AW39 -> 24.64 | L40: =[1]월별!AX39 -> 26.04 | ... P40: =[1]월별!BB39 -> 23.71 | Q40: =+AVERAGE(E40:P40) -> 26.79
D41: '24 | E41: =[1]월별!BC39 -> 27.75 | F41: =[1]월별!BD39 -> 24.36 | G41: =[1]월별!BE39 -> 26.9 | H41: =[1]월별!BF39 -> 27.1 | I41: =[1]월별!BG39 -> 26.9 | J41: =[1]월별!BH39 -> 26.9 | K41: =[1]월별!BI39 -> 25.2 | L41: =[1]월별!BJ39 -> 26.2 | ... P41: =[1]월별!BN39 -> 25.8 | Q41: =+AVERAGE(E41:P41) -> 26.2175
...

Sheet 26년개편안
